Workbook

Sheet Scheda 1
A1: TABELLA RIEPILOGATIVA
A3: SOGGETTO/I RICHIEDENTE/I
A6: INQUADRAMENTO INTERVENTI | C6: ==> | D6: Condominio | E6: 1
D7: N. Unità | E7: 2
D8: Colonnine | E8: 0 | G8: Massimale di spesa IVA inclusa | H8: PROGETTO
H9: Lavori | I9: Progettazione | K9: Prime Hub | L9: Asseverazione | N9: IVA 10% | O9: IVA 22% | P9: Sommano
I10: 0.2 | J10: 0.027366 | K10: 0.035 | L10: 0.024 | M10: 0.031595
B11: Trainanti | C11: Isolamento | G11: =IF(E7<9,E7*'Calcolo massimali'!C2,(8*'Calcolo massimali'!C2)+((E7-8)*'Calcolo massimali'!D2)) -> 80000 | I11: =ROUND(H11*$I$10,2) -> 0 | J11: =ROUND(H11*$J$10,2) -> 0 | K11: =ROUND(H11*$K$10,2) -> 0 | L11: =ROUND(H11*$L$10,2) -> 0 | M11: =ROUND(H11*$M$10,2) -> 0 | N11: =ROUND(H11*0.1,2) -> 0 | O11: =ROUND(SUM(I11:M11)*0.22,2) -> 0 | P11: =SUM(H11:O11) -> 0 | Q11: =IF(P11<=G11,"Ok","ATTENZIONE") -> Ok
C12: Sostituzione Impianti | G12: =IF(E7<9,E7*'Calcolo massimali'!C2,(8*'Calcolo massimali'!C2)+((E7-8)*'Calcolo massimali'!D2)) -> 80000 | I12: =ROUND(H12*$I$10,2) -> 0 | J12: =ROUND(H12*$J$10,2) -> 0 | K12: =ROUND(H12*$K$10,2) -> 0 | L12: =ROUND(H12*$L$10,2) -> 0 | M12: =ROUND(H12*$M$10,2) -> 0 | N12: =ROUND(H12*0.1,2) -> 0 | O12: =ROUND(SUM(I12:M12)*0.22,2) -> 0 | P12: =SUM(H12:O12) -> 0 | Q12: =IF(P12<=G12,"Ok","ATTENZIONE") -> Ok
B13: Parti Comuni | C13: Serramenti | I13: =ROUND(H13*$I$10,2) -> 0 | J13: =ROUND(H13*$J$10,2) -> 0 | K13: =ROUND(H13*$K$10,2) -> 0 | L13: =ROUND(H13*$L$10,2) -> 0 | M13: =ROUND(H13*$M$10,2) -> 0 | N13: =ROUND(H13*0.1,2) -> 0 | O13: =ROUND(SUM(I13:M13)*0.22,2) -> 0 | P13: =SUM(H13:O13) -> 0 | Q13: =IF(P13<=G13,"Ok","ATTENZIONE") -> Ok
C14: Fotovoltaico | I14: =ROUND(H14*$I$10,2) -> 0 | J14: =ROUND(H14*$J$10,2) -> 0 | K14: =ROUND(H14*$K$10,2) -> 0 | L14: =ROUND(H14*$L$10,2) -> 0 | M14: =ROUND(H14*$M$10,2) -> 0 | N14: =ROUND(H14*0.1,2) -> 0 | O14: =ROUND(SUM(I14:M14)*0.22,2) -> 0 | P14: =SUM(H14:O14) -> 0 | Q14: =IF(P14<=G14,"Ok","ATTENZIONE") -> Ok
C15: Sist. Accumulo | I15: =ROUND(H15*$I$10,2) -> 0 | J15: =ROUND(H15*$J$10,2) -> 0 | K15: =ROUND(H15*$K$10,2) -> 0 | L15: =ROUND(H15*$L$10,2) -> 0 | M15: =ROUND(H15*$M$10,2) -> 0 | N15: =ROUND(H15*0.1,2) -> 0 | O15: =ROUND(SUM(I15:M15)*0.22,2) -> 0 | P15: =SUM(H15:O15) -> 0 | Q15: =IF(P15<=G15,"Ok","ATTENZIONE") -> Ok
C16: Infr. ricarica | I16: =ROUND(H16*$I$10,2) -> 0 | J16: =ROUND(H16*$J$10,2) -> 0 | K16: =ROUND(H16*$K$10,2) -> 0 | L16: =ROUND(H16*$L$10,2) -> 0 | M16: =ROUND(H16*$M$10,2) -> 0 | N16: =ROUND(H16*0.1,2) -> 0 | O16: =ROUND(SUM(I16:M16)*0.22,2) -> 0 | P16: =SUM(H16:O16) -> 0 | Q16: =IF(P16<=G16,"Ok","ATTENZIONE") -> Ok
A17: 1 | B17: Fabio Serembe | C17: Serramenti | G17: ='Calcolo massimali'!$B$12 -> 54545.45 | I17: =ROUND(H17*$I$10,2) -> 0 | J17: =ROUND(H17*$J$10,2) -> 0 | K17: =ROUND(H17*$K$10,2) -> 0 | L17: =ROUND(H17*$L$10,2) -> 0 | M17: =ROUND(H17*$M$10,2) -> 0 | N17: =ROUND(H17*0.1,2) -> 0 | O17: =ROUND(SUM(I17:M17)*0.22,2) -> 0 | P17: =SUM(H17:O17) -> 0 | Q17: =IF(P17<=G17,"Ok","ATTENZIONE") -> Ok
C18: Schermature | G18: ='Calcolo massimali'!$B$12 -> 54545.45 | I18: =ROUND(H18*$I$10,2) -> 0 | J18: =ROUND(H18*$J$10,2) -> 0 | K18: =ROUND(H18*$K$10,2) -> 0 | L18: =ROUND(H18*$L$10,2) -> 0 | M18: =ROUND(H18*$M$10,2) -> 0 | N18: =ROUND(H18*0.1,2) -> 0 | O18: =ROUND(SUM(I18:M18)*0.22,2) -> 0 | P18: =SUM(H18:O18) -> 0 | Q18: =IF(P18<=G18,"Ok","ATTENZIONE") -> Ok
C19: BACS | G19: ='Calcolo massimali'!$B$14 -> 13636.36 | I19: =ROUND(H19*$I$10,2) -> 0 | J19: =ROUND(H19*$J$10,2) -> 0 | K19: =ROUND(H19*$K$10,2) -> 0 | L19: =ROUND(H19*$L$10,2) -> 0 | M19: =ROUND(H19*$M$10,2) -> 0 | N19: =ROUND(H19*0.1,2) -> 0 | O19: =ROUND(SUM(I19:M19)*0.22,2) -> 0 | P19: =SUM(H19:O19) -> 0 | Q19: =IF(P19<=G19,"Ok","ATTENZIONE") -> Ok
A20: 2 | B20: Mario Rossi | C20: Serramenti | G20: ='Calcolo massimali'!$B$12 -> 54545.45 | I20: =ROUND(H20*$I$10,2) -> 0 | J20: =ROUND(H20*$J$10,2) -> 0 | K20: =ROUND(H20*$K$10,2) -> 0 | L20: =ROUND(H20*$L$10,2) -> 0 | M20: =ROUND(H20*$M$10,2) -> 0 | N20: =ROUND(H20*0.1,2) -> 0 | O20: =ROUND(SUM(I20:M20)*0.22,2) -> 0 | P20: =SUM(H20:O20) -> 0 | Q20: =IF(P20<=G20,"Ok","ATTENZIONE") -> Ok
C21: Schermature | G21: ='Calcolo massimali'!$B$12 -> 54545.45 | I21: =ROUND(H21*$I$10,2) -> 0 | J21: =ROUND(H21*$J$10,2) -> 0 | K21: =ROUND(H21*$K$10,2) -> 0 | L21: =ROUND(H21*$L$10,2) -> 0 | M21: =ROUND(H21*$M$10,2) -> 0 | N21: =ROUND(H21*0.1,2) -> 0 | O21: =ROUND(SUM(I21:M21)*0.22,2) -> 0 | P21: =SUM(H21:O21) -> 0 | Q21: =IF(P21<=G21,"Ok","ATTENZIONE") -> Ok
C22: BACS | G22: ='Calcolo massimali'!$B$14 -> 13636.36 | I22: =ROUND(H22*$I$10,2) -> 0 | J22: =ROUND(H22*$J$10,2) -> 0 | K22: =ROUND(H22*$K$10,2) -> 0 | L22: =ROUND(H22*$L$10,2) -> 0 | M22: =ROUND(H22*$M$10,2) -> 0 | N22: =ROUND(H22*0.1,2) -> 0 | O22: =ROUND(SUM(I22:M22)*0.22,2) -> 0 | P22: =SUM(H22:O22) -> 0 | Q22: =IF(P22<=G22,"Ok","ATTENZIONE") -> Ok
E23: Somme | H23: =SUM(H11:H22) -> 0 | I23: =SUM(I11:I22) -> 0 | J23: =SUM(J11:J22) -> 0 | K23: =SUM(K11:K22) -> 0 | L23: =SUM(L11:L22) -> 0 | M23: =SUM(M11:M22) -> 0 | N23: =SUM(N11:N22) -> 0 | O23: =SUM(O11:O22) -> 0 | P23: =SUM(P11:P22) -> 0
N25: Cessione | P25: =P23*1.1 -> 0
N27: Prezzo d'acquisto 101 | P27: =P23*1.01 -> 0
N29: Guadagno o Perdita | P29: =P27-P23 -> 0
G31: TOT. COSTI NOI | H31: TOT. CMP | I31: UTILE | J31: MARGINE %
A32: PRATICA 1 | B32: TOTALE TRAINATI E COMUNI | C32: Serramenti | H32: =SUMIF($C$11:$C$22,$C32,$H$11:$H$22) -> 0 | I32: =H32-G32 -> 0 | J32: =I32/H32 -> #DIV/0!
C33: Schermature | H33: =SUMIF($C$11:$C$22,$C33,$H$11:$H$22) -> 0 | I33: =H33-G33 -> 0 | J33: =I33/H33 -> #DIV/0!
C34: BACS | H34: =SUMIF($C$11:$C$22,$C34,$H$11:$H$22) -> 0 | I34: =H34-G34-G35 -> 0 | J34: =I34/H34 -> #DIV/0!
C35: Elettricista (building automation)
C36: Fotovoltaico | H36: =SUMIF($C$11:$C$22,$C36,$H$11:$H$22) -> 0 | I36: =H36+H37+H38-G36 -> 0 | J36: =I36/H36 -> #DIV/0!
C37: Infr. Ricarica | H37: =SUMIF($C$11:$C$22,$C37,$H$11:$H$22) -> 0
C38: Sist. Accumulo | H38: =SUMIF($C$11:$C$22,$C38,$H$11:$H$22) -> 0
C39: Isolamento | H39: =SUMIF($C$11:$C$22,$C39,$H$11:$H$22) -> 0 | I39: =H39-G39-G40 -> 0 | J39: =I39/H39 -> #DIV/0!
C40: Lattoneria (edile)
C41: Sostituzione impianti | H41: =SUMIF($C$11:$C$22,$C41,$H$11:$H$22) -> 0 | I41: =H41+H42-G41 -> 0 | J41: =I41/H41 -> #DIV/0!
C42: Riscaldamento | H42: =SUMIF($C$11:$C$22,$C42,$H$11:$H$22) -> 0
C43: Progetto | G43: =H23*10% -> 0 | H43: =I23 -> 0 | I43: =H43-G43 -> 0 | J43: =I43/H43 -> #DIV/0!
C44: Asseverazione Tecnica | G44: =H44 -> 0 | H44: =L23 -> 0 | I44: =H44-G44 -> 0 | J44: =I44/H44 -> #DIV/0!
C45: Asseverazione Fiscale | G45: =H45 -> 0 | H45: =M23 -> 0 | I45: =H45-G45 -> 0 | J45: =I45/H45 -> #DIV/0!
C46: Polizze 2% tutto tranne IVA | F46: 0.02 | G46: =SUM(H23:M23)*F46 -> 0 | I46: =H46-G46 -> 0
C47: Fascicolazione 3.5 | F47: 0.035 | G47: =P23*F47 -> 0 | I47: =H47-G47 -> 0
...

Sheet Calcolo massimali
A1: TRAINANTI | B1: Singola | C1: Da 2 a 8 | D1: Da 8+
A2: Involucro > 25% | B2: 50000 | C2: 40000 | D2: 30000
A3: Riscaldamento Centralizzato | C3: 20000 | D3: 15000
A4: Riscaldamento Autonomo | B4: 30000
A5: Sismica | B5: 96000 | C5: 96000 | D5: 96000
A9: TRAINATI
A10: Coibentazione involucro (compresi serramenti) | B10: 54545.45
A11: Sostituzione impianto riscaldamento autonomo | B11: 27272.73
A12: Schermature Solari | B12: 54545.45
A13: Caldaie a Biomassa | B13: 27272.73
A14: BACS - Sistemi multimediali controllo impianti | B14: 13636.36
A15: Microgeneratori | B15: 90909.09
A16: Impianto Fotovoltaico | B16: 2400 | C16: x Kw
A17: Impianto Fotovoltaico ristrutturazione | B17: 1600 | C17: x Kw
A18: Accumulo Elettrico | B18: 1000 | C18: x Kw
B19: Singola | C19: Da 2 a 8 | D19: Da 8+
A20: Colonnina ricarica veicoli elettrici | B20: 2000 | C20: 1500 | D20: 1200

Sheet Lista condomini
A1: N. | B1: Nome | C1: Cognome | D1: Codice fiscale | E1: Millesimi | F1: Telefono | G1: Email | H1: Foglio | I1: Particella | J1: Subalterno | K1: Categoria catastale | L1: Superficie catastale
A2: 1 | B2: Fabio | C2: Serembe | D2: SRMFBA90R12A465L | E2: 1 | F2: 3401821790 | G2: fabio.serembe@gmail.com | H2: 3 | I2: 4 | J2: 5 | K2: 6 | L2: 7
A3: 2 | B3: Mario | C3: Rossi | D3: MARRRS87F21A465G | E3: 5 | F3: 123456789 | G3: mario.rossi@example.test | H3: 24 | I3: 35 | J3: 46 | K3: 87 | L3: 26
